Workbook

Sheet data
A1: Company | B1: Pharmacia & Upjohn | C1: Crane PlasticsTimebertech | D1: Nitta Casing | E1: Doe Run | F1: Kal Kan-1 | G1: Crane Plastics siding | H1: Hoechst Marrion Roussel | I1: Shultz Foods | J1: PP&L | K1: Duquesne Light | L1: Guest | M1: NY Life | N1: Genentech | O1: C.B. Fleet | P1: NIBCO | Q1: Hutchinson Sealing systems | R1: Black Butte Coal | S1: Techneglas | T1: SNC-US | U1: Snyder's of Hanover | V1: Agilent Technology | W1: Infineon | X1: Copella Fruit Juices | Y1: PGI#1 - Benson | Z1: GlaxoSmithKline | AA1: B Braun | AB1: B Braun Mold Shop | AC1: Dana#2 (Perfect Circle) | AD1: Effem | AE1: Borg Warner | AF1: Unilever | AG1: RBX Industries | AH1: Convergent Label Tech | AI1: BGE#1 | AJ1: BGE#2 | AK1: BGE#3 | AL1: BGE#5 | AM1: BGE#6 | AN1: Andersen #1 | AO1: Lutherwood | AP1: Borg#2 | AQ1: Ocadian Care Centers | AR1: Philips - Salina | AS1: Quest | AT1: Dana #1 | AU1: Mars Line 8 | AV1: Mars IP | AW1: Mars#2 | AX1: Mars3 | AY1: Mars#4 | AZ1: Philips-Bath | BA1: Kal Kan-2 | BB1: PGI Gainesville | BC1: DSM2 | BD1: Dynamic Windows | BE1: RIM | BF1: Impax Laboratories | BG1: Toray Membrane | BH1: Elan | BI1: American Licorice | BJ1: PGI3 | BK1: Royal Canadian Mint | BL1: Dana #3 | BM1: Masterfoods Mattoon | BN1: Santa Barbara Co. | BO1: Nestle | BP1: Rockline | BQ1: Masterfoods - Cleveland | BR1: Masterfoods - Waco | BS1: IP - Seaboard | BT1: Alkermes | BU1: Masterfoods Columbus | BV1: Lafarge Buchanan | BW1: Marathon | BX1: Armstrong | BY1: Andersen #2 | BZ1: IP - Maplesville | CA1: Placer Dome | CB1: Westinghouse | CC1: San Manuel Casino | CD1: Pepsi-Transport | CE1: Toray Production | CF1: Toray Test Lab | CG1: Lafarge Palatka | CH1: Pepsi-Roanoke | CI1: Pepsi-Hayward | CJ1: DSM Pharmaceuticals | CK1: SkyTrain | CL1: GSK#2 | CM1: Pepsi Detroit | CN1: Pepsi Columbia | CO1: GPA | CP1: Unilock | CQ1: Corn Products | CR1: PGI - Landisville | CS1: Valmont Maint | CT1: Valmont Production | CU1: Mackay Envelope | CV1: Rohm & Haas | CW1: Pepsi - Mississauga | CX1: Lafarge Silver Grove | CY1: Trustile Doors | CZ1: Trustile2 | DA1: Toray Plastics | DB1: Toray Plastics - Day Shift | DC1: Trustile #3 | DD1: Boulder Scientific | DE1: Buckeye Partners | DF1: Toyota Woodstock | DG1: Toyota Cambridge | DH1: Medtronic | DI1: Thermo Fisher Scientific | DJ1: LM Glasfiber | DK1: Capri | DL1: EGS Electrical | DM1: Xerox Canada | DN1: Campbell's | DO1: Royal Canadian Mint #3 | DP1: American Refining Group | DQ1: SCA Tissue | DR1: Imperial Sugar | DS1: Nike-Northridge | DT1: Nike-Winchester | DU1: BP - Husky | DV1: Oberthur | DW1: Nike-Shelby | DX1: Compass Minerals | DY1: SITA | DZ1: Kellogg's San Jose | EA1: Kellogg Wyoming | EB1: Kellogg Florence | EC1: Tessera | ED1: Shearer's Foods | EE1: Akzo Nobel | EF1: Kellogg's Chicago | EG1: Kellogg's Utah | EH1: Kellogg's London | EI1: Kellogg's Augusta | EJ1: Sunnyvale WPCP | EK1: Nisshinbo | EL1: Things Remembered | EM1: Kellogg - Kansas City | EN1: Mars Canada | EO1: Kellogg Zanesville | EP1: Kellogg Seelyville | EQ1: Vale | ER1: LMS Temp | ES1: LMS FT | ET1: Aptalis Pharmatech | EU1: Nestle Dreyers | EV1: MIBA Bearings | EW1: Silfex | EX1: Under Armour | EY1: Nissin Brake | EZ1: Baxter | FA1: Blue Bird | FB1: Insinkerator | FC1: Bay Valley Foods | FD1: PPL Security | FE1: United Airlines | FF1: Buddig | FG1: Menasha | FH1: Pepsi - San Antonio | FI1: Pepsi - Mesquite | FJ1: President Container | FK1: PCS Phos[hate | FL1: MackayMitchell Envelope | FM1: Menasha Packaging 2 | FN1: Baptista's Bakery | FO1: S&D Core | FP1: S&D Non-Core | FQ1: Continental Automotive | FR1: Beckman & Coulter | FS1: Nestle Purina PetCare | FT1: Harbar | FU1: Continental Building Products | FV1: Diamond Foods | FW1: Nestle Freehold | FX1: Nestle Fort Dodge | FY1: Compass Minerals | FZ1: Nestle Jefferson | GA1: Dutchland | GB1: Andersen | GC1: Medtronic | GD1: Essity Neenah | GE1: Essity South Glen Falls | GF1: Essity Middletown | GG1: Essity Harrodsburg | GH1: BD Four Oaks NC | GI1: BD Sparks MD | GJ1: BD Columbus NE | GK1: BD Covington GA | GL1: Hemlock Legacy | GM1: UTZ Plant 3 | GN1: UTZ Plant 4 | GO1: UTZ Plant 2 | GP1: Hemlock Finishing | GQ1: Campbells Beloit WE | GR1: Andersen Windows Maintenance | GS1: Westrock Demopolis, AL | GT1: Mondelēz Richmond VA | GU1: Prysmian | GV1: Averages
A2: Headcount | B2: 598 | C2: 30 | D2: 75 | E2: 610 | F2: 185 | G2: 138 | H2: 615 | I2: 162 | J2: 53 | K2: 38 | L2: 284 | M2: 66 | N2: 418 | O2: 242 | P2: 309 | Q2: 17 | R2: 93 | S2: 492 | T2: 127 | U2: 291 | V2: 824 | W2: 1111 | X2: 39 | Y2: 189 | Z2: 217 | AA2: 85 | AB2: 19 | AC2: 266 | AD2: 74 | AE2: 9 | AF2: 14 | AG2: 94 | AH2: 38 | AI2: 63 | AJ2: 44 | AK2: 7 | AL2: 290 | AM2: 22 | AN2: 28 | AO2: 17 | AP2: 42 | AQ2: 72 | AR2: 473 | AS2: 52 | AT2: 849 | AU2: 18 | AV2: 55 | AW2: 276 | AX2: 41 | AY2: 32 | BA2: 16 | BB2: 67 | BC2: 66 | BD2: 180 | BE2: 255 | BF2: 145 | BG2: 16 | BH2: 83 | BI2: 209 | BJ2: 103 | BK2: 70 | BL2: 234 | BM2: 85 | BN2: 11 | BO2: 141 | BP2: 214 | BQ2: 485 | BR2: 469 | BS2: 100 | BT2: 56 | BU2: 226 | BV2: 57 | BW2: 219 | BX2: 119 | BY2: 2421 | BZ2: 103 | CA2: 111 | CB2: 447 | CC2: 294 | CD2: 9 | CE2: 64 | CF2: 34 | CG2: 103 | CH2: 51 | CI2: 101 | CJ2: 40 | CK2: 43 | CL2: 246 | CM2: 32 | CN2: 31 | CO2: 451 | CP2: 107 | CQ2: 29 | CR2: 52 | CS2: 21 | CT2: 19 | CU2: 181 | CV2: 78 | CW2: 17 | CX2: 77 | CY2: 123 | CZ2: 25 | DA2: 55 | DB2: 13 | DC2: 15 | DD2: 41 | DE2: 26 | DF2: 108 | DG2: 224 | DH2: 443 | DI2: 401 | DJ2: 207 | DK2: 156 | DL2: 90 | DM2: 55 | DN2: 91 | DO2: 174 | DP2: 71 | DQ2: 248 | DR2: 224 | DS2: 404 | DT2: 101 | DU2: 239 | DV2: 241 | DW2: 859 | DX2: 100 | DY2: 82 | DZ2: 96 | EA2: 160 | EB2: 101 | EC2: 41 | ED2: 362 | EE2: 470 | EF2: 277 | EG2: 144 | EH2: 18 | EI2: 345 | EJ2: 22 | EK2: 244 | EL2: 126 | EM2: 269 | EN2: 31 | EO2: 249 | EP2: 189 | EQ2: 937 | ER2: 71 | ES2: 103 | ET2: 83 | EU2: 170 | EV2: 193 | EW2: 206 | EX2: 718 | EY2: 886 | EZ2: 1757 | FA2: 924 | FB2: 983 | FC2: 259 | FD2: 136 | FE2: 566 | FF2: 707 | FG2: 189 | FH2: 35 | FI2: 135 | FJ2: 251 | FK2: 236 | FL2: 127 | FM2: 240 | FN2: 338 | FO2: 296 | FP2: 140 | FQ2: 282 | FR2: 131 | FS2: 113 | FT2: 126 | FU2: 179 | FV2: 187 | FW2: 123 | FX2: 207 | FY2: 211 | FZ2: 184 | GA2: 195 | GB2: 346 | GC2: 414 | GD2: 250 | GE2: 90 | GF2: 55 | GG2: 225 | GH2: 110 | GI2: 109 | GJ2: 851 | GK2: 171 | GL2: 162 | GM2: 375 | GN2: 253 | GO2: 248 | GP2: 550 | GQ2: 111 | GR2: 68 | GS2: 169 | GT2: 389 | GV2: =SUM(B2:GT2) -> 44521
A3: Shift | GD3: Southern Swing (8-hour) | GE3: Southern Swing | GF3: Southern Swing (8-hour) | GG3: 2-3-2 rotating 2 wk | GH3: Weekday 8,10-hour + 12-hour weekend fixed | GI3: Fixed M-F | GJ3: A/C=12-hr day, B/D = 12-hr night 2-3-2 plus some on 8-hour fixed M-F | GK3: 8-hr M-F, fixed | GL3: 2-3-2 rotating 2 wk | GM3: 12-hour | GN3: 12-hour | GO3: 12-hour | GP3: 2-3-2 rotating 2 wk | GQ3: 8-hr M-F, fixed | GR3: M-F, Fixed nights + Oscillating day/afternoon | GS3: 8-hr Southern Swing | GT3: 5 day, 8 hour
A4: Date | GD4: 44788 | GE4: 44880 | GF4: 44849 | GG4: 44669 | GH4: 44331 | GI4: 44150 | GJ4: 44798 | GK4: 44211 | GL4: 44896 | GM4: 44985 | GN4: 44985 | GO4: 44985 | GP4: 44896 | GQ4: 44501 | GR4: 44849 | GS4: 45304 | GT4: 45404
A5: Demographic Information
A6: What crew/shift are you assigned to?
A7: First (day) shift (8-hour or 10-hour) | P7: 50 | V7: 32 | AA7: 40 | AC7: 52 | AE7: 22 | AG7: 47 | AK7: 43 | AO7: 11 | AP7: 33 | AQ7: 34 | AS7: 60 | AT7: 37 | AZ7: 58 | BD7: 34 | BF7: 55 | BG7: 44 | BH7: 75 | BI7: 52 | BL7: 37 | BP7: 37 | BT7: 56 | BV7: 39 | CB7: 45 | CC7: 33 | CD7: 12 | CI7: 43 | CL7: 46 | CM7: 38 | CS7: 43 | CT7: 32 | CU7: 44 | CV7: 42 | CW7: 41 | CY7: 40 | CZ7: 72 | DC7: 27 | DH7: 38 | DI7: 76 | DJ7: 78 | DK7: 49 | DL7: 56 | DN7: 37 | DS7: 64 | DW7: 51 | DZ7: 49 | EA7: 38 | EB7: 36 | EC7: 61 | ED7: 37 | EE7: 50 | EF7: 37 | EI7: 35 | EJ7: 23 | EK7: 49 | EL7: 52 | EM7: 38 | EO7: 32 | EP7: 53 | ER7: 31 | ES7: 50 | ET7: 48 | EU7: 35 | EV7: 46 | EW7: 56 | EX7: 35 | EY7: 44 | EZ7: 37 | FB7: 44 | FC7: 39 | FE7: 40 | FF7: 51 | FG7: 46 | FH7: 49 | FI7: 45 | FJ7: 42 | FM7: 54 | FN7: 33 | FO7: 43 | FP7: 60 | FQ7: 38 | FR7: 66 | FS7: 31 | FT7: 52 | FU7: 43 | FV7: 34 | FW7: 44 | FX7: 32 | FZ7: 47 | GA7: 42 | GB7: 40 | GC7: 55 | GI7: 62.62 | GK7: 51 | GV7: =AVERAGE(B7:GU7) -> 44.200215
A8: Second (afternoon) shift (8-hour) | P8: 23 | V8: 28 | AA8: 28 | AC8: 23 | AE8: 22 | AG8: 30 | AK8: 43 | AO8: 44 | AP8: 36 | AQ8: 43 | AS8: 23 | AT8: 31 | AZ8: 23 | BD8: 34 | BF8: 33 | BG8: 31 | BH8: 14 | BI8: 21 | BL8: 25 | BP8: 32 | BT8: 22 | BV8: 29 | CB8: 31 | CC8: 34 | CD8: 88 | CI8: 17 | CL8: 27 | CM8: 34 | CS8: 29 | CT8: 32 | CU8: 28 | CV8: 28 | CW8: 41 | CY8: 34 | CZ8: 28 | DC8: 53 | DH8: 26 | DI8: 17 | DJ8: 13 | DK8: 26 | DL8: 25 | DN8: 31 | DS8: 36 | DW8: 32 | DZ8: 24 | EA8: 31 | EB8: 33 | EC8: 39 | ED8: 33 | EE8: 28 | EF8: 32 | EI8: 22 | EJ8: 14 | EK8: 27 | EL8: 25 | EM8: 29 | EO8: 23 | EP8: 32 | ER8: 27 | ES8: 21 | ET8: 25 | EU8: 30 | EV8: 35 | EW8: 19 | EX8: 26 | EY8: 28 | EZ8: 27 | FB8: 26 | FC8: 30 | FE8: 33 | FF8: 43 | FG8: 25 | FH8: 40 | FI8: 30 | FJ8: 32 | FM8: 24 | FN8: 33 | FO8: 32 | FP8: 28 | FQ8: 30 | FR8: 18 | FS8: 28 | FT8: 31 | FU8: 21 | FV8: 28 | FW8: 26 | FX8: 23 | FZ8: 28 | GA8: 33 | GB8: 31 | GC8: 35 | GI8: 22.43 | GK8: 21 | GV8: =AVERAGE(B8:GT8) -> 29.34871
A9: Third (night) shift (8 hour) | P9: 21 | V9: 25 | AA9: 32 | AC9: 24 | AE9: 56 | AG9: 23 | AK9: 14 | AO9: 11 | AP9: 31 | AQ9: 23 | AS9: 17 | AT9: 32 | AZ9: 17 | BD9: 32 | BF9: 12 | BG9: 25 | BH9: 11 | BI9: 28 | BL9: 22 | BP9: 30 | BT9: 22 | BV9: 21 | CB9: 23 | CC9: 34 | CI9: 39 | CL9: 27 | CM9: 28 | CS9: 29 | CT9: 37 | CU9: 28 | CV9: 30 | CW9: 18 | CY9: 26 | CZ9: 0 | DC9: 20 | DH9: 19 | DI9: 8 | DJ9: 8 | DK9: 24 | DL9: 19 | DN9: 32 | DW9: 17 | DZ9: 21 | EA9: 24 | EB9: 32 | ED9: 30 | EE9: 22 | EF9: 31 | EI9: 18 | EJ9: 14 | EK9: 24 | EL9: 23 | EM9: 33 | EO9: 20 | EP9: 14 | ER9: 26 | ES9: 18 | ET9: 26 | EU9: 35 | EV9: 19 | EW9: 19 | EX9: 15 | EY9: 28 | EZ9: 32 | FB9: 22 | FC9: 29 | FE9: 27 | FF9: 6 | FG9: 28 | FH9: 11 | FI9: 21 | FJ9: 24 | FM9: 22 | FN9: 31 | FO9: 26 | FP9: 13 | FQ9: 27 | FR9: 17 | FS9: 28 | FT9: 10 | FU9: 28 | FV9: 31 | FW9: 20 | FX9: 21 | FZ9: 25 | GA9: 25 | GB9: 29 | GI9: 14.95 | GK9: 27 | GV9: =AVERAGE(B9:GU9) -> 23.392697
A10: First (day) shift (12-hour) | P10: 3 | AH10: 66 | AZ10: 1 | BB10: 61 | BL10: 3 | BS10: 61 | BZ10: 51 | CB10: 0 | CJ10: 76 | CP10: 69 | EA10: 2 | EG10: 51 | EI10: 14 | EO10: 12 | EP10: 0 | ER10: 6 | ES10: 6 | EW10: 2 | FQ10: 2 | GV10: =AVERAGE(B10:GT10) -> 25.578947
A11: Second (night) shift (12-hour) | P11: 1 | AH11: 34 | AZ11: 1 | BB11: 39 | BL11: 1 | BS11: 39 | BZ11: 43 | CB11: 0 | CJ11: 24 | CP11: 26 | EA11: 4 | EG11: 49 | EI11: 11 | EO11: 13 | EP11: 0 | ER11: 10 | ES11: 4 | EW11: 2 | FQ11: 3 | GV11: =AVERAGE(B11:GU11) -> 16
A12: Weekend crew | P12: 1 | V12: 16 | BL12: 13 | CB12: 1 | DH12: 17 | EX12: 24 | EZ12: 4 | FX12: 4 | GC12: 10 | GV12: =AVERAGE(B12:GT12) -> 10
A13: How long have you worked for this company?
A14: Less than 6 months | W14: 0 | X14: 0 | Y14: 0 | Z14: 17 | AA14: 7 | AB14: 5 | AC14: 7 | AD14: 0 | AE14: 11.1 | AF14: 14 | AG14: 18 | AH14: 16 | AI14: 0 | AJ14: 0 | AK14: 0 | AL14: 1 | AM14: 0 | AN14: 0 | AO14: 17 | AP14: 12 | AQ14: 21 | AR14: 0 | AS14: 6 | AT14: 16 | AU14: 0 | AV14: 0 | AX14: 0 | AY14: 0 | AZ14: 3 | BA14: 0 | BC14: 8 | BD14: 8 | BE14: 34 | BF14: 42 | BG14: 62 | BH14: 5 | BI14: 26 | BJ14: 10 | BK14: 24 | BL14: 27 | BM14: 0 | BN14: 12 | CH14: 10 | CI14: 6 | CJ14: 0 | CL14: 4 | CM14: 0 | CN14: 22 | CO14: 8 | CP14: 28 | CQ14: 17 | CR14: 31 | CS14: 0 | CT14: 0 | CU14: 12 | CV14: 8 | CW14: 6 | CY14: 30 | CZ14: 16 | DA14: 13 | DB14: 0 | DC14: 0 | DD14: 12 | DE14: 0 | DF14: 37 | DG14: 4 | DH14: 0 | DI14: 3 | DJ14: 62 | DK14: 5 | DL14: 6 | DM14: 0 | DN14: 23 | DO14: 4 | DP14: 1 | DQ14: 0 | DR14: 0 | DS14: 23 | DT14: 0 | DU14: 1 | DV14: 12 | DW14: 5 | DX14: 6 | DY14: 18 | DZ14: 11 | EA14: 1 | EB14: 0 | EC14: 39 | ED14: 26 | EE14: 10 | EF14: 0 | EG14: 14 | EH14: 11 | EI14: 2 | EJ14: 4 | EK14: 14 | EL14: 10 | EM14: 10 | EN14: 3 | EO14: 0 | EP14: 6 | EQ14: 5 | ER14: 49 | ES14: 0 | ET14: 5 | EU14: 3 | EV14: 4 | EW14: 4 | EX14: 8 | EY14: 20 | EZ14: 10 | FA14: 14 | FC14: 10 | FE14: 0 | FF14: 9 | FG14: 2 | FH14: 0 | FI14: 15 | FJ14: 12 | FK14: 0 | FL14: 5 | FM14: 9 | FN14: 25 | FO14: 13 | FP14: 10 | FQ14: 5 | FR14: 16 | FS14: 10 | FT14: 19 | FV14: 25 | FW14: 5 | FX14: 5 | FY14: 0 | FZ14: 7 | GA14: 17 | GB14: 19 | GC14: 20 | GD14: 11 | GE14: 15 | GF14: 3 | GG14: 19 | GH14: 20 | GI14: 20 | GJ14: 13 | GK14: 15 | GL14: 4 | GM14: 10 | GN14: 9 | GO14: 5 | GP14: 25 | GQ14: 25 | GR14: 16 | GS14: 3 | GV14: =AVERAGE(B14:GS14) -> 10.562745
A15: 6 months to 1 year | B15: 9 | H15: 1 | I15: 26 | J15: 0 | K15: 11 | M15: 6 | N15: 46 | O15: 26 | P15: 18 | Q15: 12 | R15: 6 | S15: 13 | T15: 7 | U15: 26 | V15: 65 | W15: 8 | X15: 18 | Y15: 0 | Z15: 3 | AA15: 2 | AB15: 5 | AC15: 3 | AD15: 6 | AE15: 0 | AF15: 7 | AG15: 6 | AH15: 0 | AI15: 11 | AJ15: 0 | AK15: 0 | AL15: 1 | AM15: 0 | AN15: 0 | AO15: 6 | AP15: 15 | AQ15: 14 | AR15: 0 | AS15: 8 | AT15: 0 | AU15: 28 | AV15: 6 | AX15: 24 | AY15: 0 | AZ15: 4 | BA15: 0 | BB15: 10 | BC15: 14 | BD15: 10 | BE15: 8 | BF15: 39 | BG15: 0 | BH15: 10 | BI15: 8 | BJ15: 5 | BK15: 4 | BL15: 12 | BM15: 0 | BN15: 6 | CH15: 10 | CI15: 12 | CJ15: 17 | CL15: 5 | CM15: 0 | CN15: 11 | CO15: 6 | CP15: 8 | CQ15: 0 | CR15: 12 | CS15: 0 | CT15: 21 | CU15: 3 | CV15: 17 | CW15: 6 | CY15: 16 | CZ15: 16 | DA15: 13 | DB15: 0 | DC15: 27 | DD15: 12 | DE15: 11 | DF15: 18 | DG15: 8 | DH15: 0 | DI15: 14 | DJ15: 37 | DK15: 12 | DL15: 1 | DM15: 0 | DN15: 2 | DO15: 9 | DP15: 0 | DQ15: 1 | DR15: 0 | DS15: 19 | DT15: 3 | DU15: 2 | DV15: 17 | DW15: 5 | DX15: 8 | DY15: 1 | DZ15: 8 | EA15: 19 | EB15: 0 | EC15: 5 | ED15: 10 | EE15: 6 | EF15: 0 | EG15: 15 | EH15: 6 | EI15: 4 | EJ15: 0 | EK15: 12 | EL15: 16 | EM15: 0 | EN15: 3 | EO15: 6 | EP15: 16 | EQ15: 1 | ER15: 6 | ES15: 2 | ET15: 14 | EU15: 5 | EV15: 5 | EW15: 5 | EX15: 13 | EY15: 17 | EZ15: 8 | FA15: 7 | FC15: 18 | FE15: 1 | FF15: 10 | FG15: 7 | FH15: 14 | FI15: 6 | FJ15: 16 | FK15: 0 | FL15: 8 | FM15: 11 | FN15: 20 | FO15: 15 | FP15: 14 | FQ15: 7 | FR15: 17 | FS15: 16 | FT15: 10 | FV15: 11 | FW15: 7 | FX15: 16 | FY15: 6 | FZ15: 7 | GA15: 13 | GB15: 10 | GC15: 9 | GD15: 16 | GE15: 6 | GF15: 7 | GG15: 15 | GH15: 12 | GI15: 13 | GJ15: 12 | GK15: 14 | GL15: 18 | GM15: 17 | GN15: 12 | GO15: 11 | GP15: 20 | GQ15: 11 | GR15: 7 | GS15: 8 | GV15: =AVERAGE(B15:GS15) -> 9.6449704
A16: 1 to 5 years | B16: 22 | H16: 30 | I16: 38 | J16: 11 | K16: 16 | M16: 3 | N16: 36 | O16: 30 | P16: 20 | Q16: 18 | R16: 26 | S16: 37 | T16: 41 | U16: 32 | V16: 17 | W16: 10 | X16: 51 | Y16: 32 | Z16: 25 | AA16: 19 | AB16: 21 | AC16: 22 | AD16: 10 | AE16: 78 | AF16: 14 | AG16: 26 | AH16: 47 | AI16: 11 | AJ16: 2 | AK16: 0 | AL16: 7 | AM16: 0 | AN16: 39 | AO16: 50 | AP16: 38 | AQ16: 39 | AR16: 11 | AS16: 46 | AT16: 40 | AU16: 22 | AV16: 2 | AX16: 24 | AY16: 28 | AZ16: 8 | BA16: 75 | BB16: 36 | BC16: 38 | BD16: 58 | BE16: 50 | BF16: 19 | BG16: 19 | BH16: 70 | BI16: 9 | BJ16: 20 | BK16: 17 | BL16: 11 | BM16: 18 | BN16: 50 | CH16: 30 | CI16: 20 | CJ16: 36 | CK16: 9 | CL16: 27 | CM16: 22 | CN16: 26 | CO16: 37 | CP16: 45 | CQ16: 24 | CR16: 14 | CS16: 0 | CT16: 5 | CU16: 14 | CV16: 30 | CW16: 6 | CY16: 32 | CZ16: 52 | DA16: 33 | DB16: 0 | DC16: 60 | DD16: 44 | DE16: 44 | DF16: 8 | DG16: 28 | DH16: 38 | DI16: 15 | DJ16: 2 | DK16: 53 | DL16: 28 | DM16: 0 | DN16: 9 | DO16: 60 | DP16: 37 | DQ16: 23 | DR16: 29 | DS16: 25 | DT16: 36 | DU16: 47 | DV16: 34 | DW16: 32 | DX16: 24 | DY16: 63 | DZ16: 24 | EA16: 80 | EB16: 38 | EC16: 49 | ED16: 40 | EE16: 25 | EF16: 22 | EG16: 46 | EH16: 28 | EI16: 25 | EJ16: 50 | EK16: 31 | EL16: 29 | EM16: 41 | EN16: 52 | EO16: 25 | EP16: 62 | EQ16: 19 | ER16: 45 | ES16: 31 | ET16: 43 | EU16: 25 | EV16: 26 | EW16: 38 | EX16: 66 | EY16: 22 | EZ16: 13 | FA16: 34 | FC16: 49 | FE16: 2 | FF16: 16 | FG16: 30 | FH16: 29 | FI16: 34 | FJ16: 58 | FK16: 1 | FL16: 26 | FM16: 23 | FN16: 46 | FO16: 28 | FP16: 42 | FQ16: 37 | FR16: 40 | FS16: 30 | FT16: 46 | FV16: 45 | FW16: 29 | FX16: 30 | FY16: 25 | FZ16: 31 | GA16: 45 | GB16: 42 | GC16: 46 | GD16: 34 | GE16: 21 | GF16: 10 | GG16: 6 | GH16: 50 | GI16: 31 | GJ16: 35 | GK16: 46 | GL16: 16 | GM16: 29 | GN16: 38 | GO16: 30 | GP16: 22 | GQ16: 37 | GR16: 28 | GS16: 18 | GV16: =AVERAGE(B16:GS16) -> 30
A17: 6 to 10 years | B17: 12 | H17: 18 | I17: 31 | J17: 0 | K17: 0 | M17: 9 | N17: 11 | O17: 10 | P17: 13 | Q17: 41 | R17: 15 | S17: 24 | T17: 4 | U17: 24 | V17: 6 | W17: 12 | X17: 15 | Y17: 14 | Z17: 9 | AA17: 34 | AB17: 42 | AC17: 14 | AD17: 25 | AE17: 11 | AF17: 0 | AG17: 15 | AH17: 21 | AI17: 24 | AJ17: 2 | AK17: 0 | AL17: 3 | AM17: 0 | AN17: 7 | AO17: 0 | AP17: 18 | AQ17: 8 | AR17: 16 | AS17: 17 | AT17: 44 | AU17: 6 | AV17: 26 | AX17: 15 | AY17: 25 | AZ17: 25 | BA17: 19 | BB17: 16 | BC17: 17 | BD17: 20 | BE17: 8 | BF17: 1 | BG17: 6 | BH17: 6 | BI17: 20 | BJ17: 49 | BK17: 23 | BL17: 24 | BM17: 14 | BN17: 19 | CH17: 18 | CI17: 28 | CJ17: 19 | CK17: 14 | CL17: 13 | CM17: 31 | CN17: 11 | CO17: 18 | CP17: 12 | CQ17: 14 | CR17: 6 | CS17: 24 | CT17: 26 | CU17: 28 | CV17: 22 | CW17: 24 | CY17: 22 | CZ17: 12 | DA17: 20 | DB17: 15 | DC17: 13 | DD17: 12 | DE17: 7 | DF17: 8 | DG17: 15 | DH17: 36 | DI17: 12 | DJ17: 0 | DK17: 19 | DL17: 59 | DM17: 4 | DN17: 7 | DO17: 6 | DP17: 20 | DQ17: 24 | DR17: 18 | DS17: 12 | DT17: 11 | DU17: 6 | DV17: 8 | DW17: 14 | DX17: 14 | DY17: 12 | DZ17: 11 | EA17: 0 | EB17: 11 | EC17: 5 | ED17: 16 | EE17: 16 | EF17: 2 | EG17: 17 | EH17: 11 | EI17: 16 | EJ17: 14 | EK17: 28 | EL17: 23 | EM17: 4 | EN17: 29 | EO17: 50 | EP17: 6 | EQ17: 30 | ER17: 0 | ES17: 32 | ET17: 20 | EU17: 18 | EV17: 11 | EW17: 39 | EX17: 12 | EY17: 16 | EZ17: 10 | FA17: 14 | FC17: 16 | FE17: 0 | FF17: 20 | FG17: 13 | FH17: 17 | FI17: 18 | FJ17: 6 | FK17: 10 | FL17: 15 | FM17: 17 | FN17: 5 | FO17: 20 | FP17: 16 | FQ17: 5 | FR17: 26 | FS17: 8 | FT17: 17 | FV17: 19 | FW17: 18 | FX17: 17 | FY17: 16 | FZ17: 22 | GA17: 4 | GB17: 8 | GC17: 18 | GD17: 13 | GE17: 2 | GF17: 26 | GG17: 27 | GH17: 16 | GI17: 12 | GJ17: 14 | GK17: 9 | GL17: 17 | GM17: 8 | GN17: 17 | GO17: 14 | GP17: 11 | GQ17: 15 | GR17: 15 | GS17: 18 | GV17: =AVERAGE(B17:GS17) -> 15.694118
A18: 11 to 15 years | B18: 21 | H18: 21 | I18: 3 | J18: 15 | K18: 0 | M18: 21 | N18: 6 | O18: 4 | P18: 32 | Q18: 29 | R18: 13 | S18: 8 | T18: 44 | U18: 10 | V18: 2 | W18: 28 | X18: 5 | Y18: 15 | Z18: 18 | AA18: 15 | AB18: 5 | AC18: 3 | AD18: 59 | AE18: 0 | AF18: 50 | AG18: 15 | AH18: 13 | AI18: 24 | AJ18: 23 | AK18: 0 | AL18: 28 | AM18: 23 | AN18: 14 | AO18: 17 | AP18: 0 | AQ18: 11 | AR18: 11 | AS18: 15 | AT18: 0 | AU18: 44 | AV18: 40 | AX18: 29 | AY18: 38 | AZ18: 6 | BA18: 6 | BB18: 10 | BC18: 5 | BD18: 3 | BE18: 0 | BF18: 0 | BG18: 0 | BH18: 8 | BI18: 14 | BJ18: 9 | BK18: 11 | BL18: 12 | BM18: 38 | BN18: 12 | CH18: 6 | CI18: 14 | CJ18: 21 | CK18: 7 | CL18: 5 | CM18: 6 | CN18: 7 | CO18: 9 | CP18: 6 | CQ18: 7 | CR18: 10 | CS18: 19 | CT18: 5 | CU18: 15 | CV18: 10 | CW18: 6 | CY18: 1 | CZ18: 4 | DA18: 22 | DB18: 85 | DC18: 0 | DD18: 15 | DE18: 4 | DF18: 15 | DG18: 29 | DH18: 6 | DI18: 7 | DJ18: 0 | DK18: 11 | DL18: 6 | DM18: 4 | DN18: 0 | DO18: 4 | DP18: 1 | DQ18: 21 | DR18: 15 | DS18: 10 | DT18: 31 | DU18: 13 | DV18: 16 | DW18: 29 | DX18: 18 | DY18: 5 | DZ18: 1 | EA18: 1 | EB18: 20 | EC18: 2 | ED18: 6 | EE18: 14 | EF18: 22 | EG18: 8 | EH18: 22 | EI18: 21 | EJ18: 18 | EK18: 15 | EL18: 20 | EM18: 1 | EN18: 3 | EO18: 13 | EP18: 10 | EQ18: 19 | ER18: 0 | ES18: 16 | ET18: 10 | EU18: 12 | EV18: 24 | EW18: 10 | EX18: 1 | EY18: 11 | EZ18: 19 | FA18: 8 | FC18: 5 | FE18: 5 | FF18: 13 | FG18: 11 | FH18: 11 | FI18: 9 | FJ18: 2 | FK18: 9 | FL18: 10 | FM18: 11 | FN18: 3 | FO18: 13 | FP18: 14 | FQ18: 4 | FR18: 2 | FS18: 13 | FT18: 6 | FW18: 1 | FX18: 7 | FY18: 19 | FZ18: 8 | GA18: 7 | GB18: 17 | GC18: 5 | GD18: 0 | GE18: 4 | GF18: 17 | GG18: 8 | GH18: 2 | GI18: 2 | GJ18: 10 | GK18: 8 | GL18: 25 | GM18: 11 | GN18: 11 | GO18: 14 | GP18: 15 | GQ18: 12 | GR18: 3 | GS18: 15 | GV18: =AVERAGE(B18:GS18) -> 12.544379
A19: 16 to 20 years | B19: 14 | H19: 16 | I19: 1 | J19: 49 | K19: 3 | M19: 21 | N19: 1 | O19: 8 | P19: 1 | Q19: 0 | R19: 17 | S19: 12 | T19: 0 | U19: 2 | V19: 8 | W19: 21 | X19: 3 | Y19: 7 | Z19: 13 | AA19: 7 | AB19: 21 | AC19: 16 | AD19: 1 | AE19: 0 | AF19: 0 | AG19: 12 | AH19: 0 | AI19: 16 | AJ19: 16 | AK19: 14 | AL19: 17 | AM19: 18 | AN19: 32 | AO19: 0 | AP19: 8 | AQ19: 3 | AR19: 17 | AS19: 4 | AT19: 0 | AU19: 0 | AV19: 0 | AX19: 5 | AY19: 0 | AZ19: 24 | BA19: 0 | BB19: 2 | BC19: 8 | BD19: 0 | BE19: 0 | BF19: 0 | BG19: 6 | BH19: 1 | BI19: 6 | BJ19: 1 | BK19: 11 | BL19: 14 | BM19: 18 | BN19: 0 | CH19: 4 | CI19: 7 | CJ19: 2 | CK19: 19 | CL19: 20 | CM19: 3 | CN19: 15 | CO19: 5 | CP19: 1 | CQ19: 14 | CR19: 2 | CS19: 24 | CT19: 5 | CU19: 11 | CV19: 5 | CW19: 29 | CY19: 0 | CZ19: 0 | DC19: 0 | DD19: 5 | DE19: 11 | DF19: 12 | DG19: 16 | DH19: 7 | DI19: 8 | DJ19: 0 | DL19: 0 | DM19: 14 | DN19: 7 | DO19: 5 | DP19: 0 | DQ19: 2 | DR19: 8 | DS19: 7 | DT19: 14 | DU19: 7 | DV19: 11 | DW19: 10 | DX19: 7 | DY19: 0 | DZ19: 13 | EA19: 0 | EB19: 18 | EC19: 0 | ED19: 0 | EE19: 6 | EF19: 19 | EG19: 0 | EH19: 0 | EI19: 9 | EJ19: 4 | EK19: 0 | EL19: 1 | EM19: 2 | EN19: 3 | EO19: 4 | EP19: 0 | EQ19: 9 | ER19: 0 | ES19: 14 | ET19: 0 | EU19: 12 | EV19: 2 | EW19: 2 | EX19: 0 | EY19: 11 | EZ19: 9 | FA19: 6 | FC19: 1 | FE19: 11 | FF19: 11 | FG19: 8 | FH19: 3 | FI19: 6 | FJ19: 3 | FK19: 2 | FL19: 14 | FM19: 12 | FN19: 1 | FO19: 8 | FP19: 3 | FQ19: 8 | FR19: 0 | FS19: 2 | FT19: 2 | FW19: 11 | FX19: 6 | FY19: 8 | FZ19: 3 | GA19: 6 | GB19: 2 | GC19: 2 | GD19: 0 | GE19: 13 | GF19: 9 | GG19: 8 | GH19: 0 | GI19: 9 | GJ19: 8 | GK19: 5 | GL19: 13 | GM19: 6 | GN19: 6 | GO19: 7 | GP19: 4 | GQ19: 0 | GR19: 1 | GS19: 14 | GV19: =AVERAGE(B19:GS19) -> 7.1807229
A20: Over 20 years | B20: 22 | H20: 5 | I20: 1 | J20: 25 | K20: 71 | M20: 39 | N20: 0 | O20: 22 | P20: 17 | Q20: 0 | R20: 23 | S20: 6 | T20: 4 | U20: 5 | V20: 3 | W20: 18 | X20: 8 | Y20: 30 | Z20: 13 | AA20: 15 | AB20: 0 | AC20: 36 | AD20: 0 | AE20: 0 | AF20: 14 | AG20: 8 | AH20: 3 | AI20: 14 | AJ20: 58 | AK20: 86 | AL20: 44 | AM20: 59 | AN20: 7 | AO20: 11 | AP20: 10 | AQ20: 3 | AR20: 44 | AS20: 4 | AT20: 0 | AU20: 0 | AV20: 27 | AX20: 2 | AY20: 9 | AZ20: 29 | BA20: 0 | BB20: 25 | BC20: 11 | BD20: 0 | BE20: 0 | BF20: 0 | BG20: 6 | BH20: 0 | BI20: 17 | BJ20: 7 | BK20: 9 | BL20: 0 | BM20: 12 | BN20: 0 | CH20: 22 | CI20: 12 | CJ20: 5 | CK20: 51 | CL20: 26 | CM20: 38 | CN20: 7 | CO20: 18 | CP20: 0 | CQ20: 24 | CR20: 27 | CS20: 33 | CT20: 37 | CU20: 17 | CV20: 9 | CW20: 24 | CY20: 0 | CZ20: 0 | DC20: 0 | DD20: 0 | DE20: 22 | DF20: 1 | DG20: 0 | DH20: 12 | DI20: 41 | DJ20: 0 | DL20: 0 | DM20: 78 | DN20: 53 | DO20: 12 | DP20: 41 | DQ20: 29 | DR20: 29 | DS20: 3 | DT20: 6 | DU20: 24 | DV20: 1 | DW20: 4 | DX20: 22 | DY20: 0 | DZ20: 32 | EA20: 0 | EB20: 14 | EC20: 0 | ED20: 2 | EE20: 22 | EF20: 35 | EG20: 0 | EH20: 22 | EI20: 22 | EJ20: 9 | EK20: 0 | EL20: 2 | EM20: 42 | EN20: 6 | EO20: 2 | EP20: 0 | EQ20: 16 | ER20: 0 | ES20: 6 | ET20: 7 | EU20: 24 | EV20: 30 | EW20: 1 | EX20: 0 | EY20: 2 | EZ20: 31 | FA20: 16 | FC20: 0 | FE20: 81 | FF20: 21 | FG20: 30 | FH20: 26 | FI20: 11 | FJ20: 4 | FK20: 77 | FL20: 19 | FM20: 16 | FN20: 0 | FO20: 3 | FP20: 2 | FQ20: 36 | FR20: 0 | FS20: 21 | FT20: 1 | FW20: 29 | FX20: 20 | FY20: 25 | FZ20: 21 | GA20: 8 | GB20: 1 | GC20: 0 | GD20: 26 | GE20: 38 | GF20: 28 | GG20: 17 | GH20: 0 | GI20: 13 | GJ20: 9 | GK20: 2 | GL20: 7 | GM20: 18 | GN20: 8 | GO20: 20 | GP20: 2 | GQ20: 0 | GR20: 30 | GS20: 27 | GV20: =AVERAGE(B20:GS20) -> 15.963855
A21: AVERAGE | B21: =(B15*0.5+B16*3+B17*8+B18*13+B19*18+B20*22.5)/100 -> 11.865 | H21: =(H15*0.5+H16*3+H17*8+H18*13+H19*18+H20*22.5)/100 -> 9.08 | I21: =(I15*0.5+I16*3+I17*8+I18*13+I19*18+I20*22.5)/100 -> 4.545 | J21: =(J15*0.5+J16*3+J17*8+J18*13+J19*18+J20*22.5)/100 -> 16.725 | K21: =(K15*0.5+K16*3+K17*8+K18*13+K19*18+K20*22.5)/100 -> 17.05 | M21: =(M15*0.5+M16*3+M17*8+M18*13+M19*18+M20*22.5)/100 -> 16.125 | N21: =(N15*0.5+N16*3+N17*8+N18*13+N19*18+N20*22.5)/100 -> 3.15 | O21: =(O15*0.5+O16*3+O17*8+O18*13+O19*18+O20*22.5)/100 -> 8.74 | P21: =(P15*0.5+P16*3+P17*8+P18*13+P19*18+P20*22.5)/100 -> 9.895 | Q21: =(Q15*0.5+Q16*3+Q17*8+Q18*13+Q19*18+Q20*22.5)/100 -> 7.65 | R21: =(R15*0.5+R16*3+R17*8+R18*13+R19*18+R20*22.5)/100 -> 11.935 | S21: =(S15*0.5+S16*3+S17*8+S18*13+S19*18+S20*22.5)/100 -> 7.645 | T21: =(T15*0.5+T16*3+T17*8+T18*13+T19*18+T20*22.5)/100 -> 8.205 | ... AE21: =(AE15*0.5+AE16*3+AE17*8+AE18*13+AE19*18+AE20*22.5)/100 -> 3.22 | AF21: =(AF14*0.25+AF15*0.75+AF16*3+AF17*8+AF18*13+AF19*18+AF20*22.5)/100 -> 10.1575 | AG21: =(AG14*0.25+AG15*0.75+AG16*3+AG17*8+AG18*13+AG19*18+AG20*22.5)/100 -> 7.98 | AH21: =(AH14*0.25+AH15*0.75+AH16*3+AH17*8+AH18*13+AH19*18+AH20*22.5)/100 -> 5.495 | AI21: =(AI15*0.5+AI16*3+AI17*8+AI18*13+AI19*18+AI20*22.5)/100 -> 11.455 | AJ21: =(AJ14*0.25+AJ15*0.75+AJ16*3+AJ17*8+AJ18*13+AJ19*18+AJ20*22.5)/100 -> 19.14 | AK21: =(AK14*0.25+AK15*0.75+AK16*3+AK17*8+AK18*13+AK19*18+AK20*22.5)/100 -> 21.87 | AL21: =(AL14*0.25+AL15*0.75+AL16*3+AL17*8+AL18*13+AL19*18+AL20*22.5)/100 -> 17.06 | AM21: =(AM14*0.25+AM15*0.75+AM16*3+AM17*8+AM18*13+AM19*18+AM20*22.5)/100 -> 19.505 | AN21: =(AN14*0.25+AN15*0.75+AN16*3+AN17*8+AN18*13+AN19*18+AN20*22.5)/100 -> 10.885 | AO21: =(AO14*0.25+AO15*0.75+AO16*3+AO17*8+AO18*13+AO19*18+AO20*22.5)/100 -> 6.2725 | AP21: =(AP14*0.25+AP15*0.75+AP16*3+AP17*8+AP18*13+AP19*18+AP20*22.5)/100 -> 6.4125 | AQ21: =(AQ14*0.25+AQ15*0.75+AQ16*3+AQ17*8+AQ18*13+AQ19*18+AQ20*22.5)/100 -> 4.6125 | ... AT21: =(AT14*0.25+AT15*0.75+AT16*3+AT17*8+AT18*13+AT19*18+AT20*22.5)/100 -> 4.76 | AU21: =(AU15*0.5+AU16*3+AU17*8+AU18*13+AU19*18+AU20*22.5)/100 -> 7 | AV21: =(AV15*0.5+AV16*3+AV17*8+AV18*13+AV19*18+AV20*22.5)/100 -> 13.445 | AX21: =(AX14*0.25+AX15*0.75+AX16*3+AX17*8+AX18*13+AX19*18+AX20*22.5)/100 -> 7.22 | AY21: =(AY14*0.25+AY15*0.75+AY16*3+AY17*8+AY18*13+AY19*18+AY20*22.5)/100 -> 9.805 | AZ21: =(AZ14*0.25+AZ15*0.75+AZ16*3+AZ17*8+AZ18*13+AZ19*18+AZ20*22.5)/100 -> 13.9025 | BA21: =(BA14*0.25+BA15*0.75+BA16*3+BA17*8+BA18*13+BA19*18+BA20*22.5)/100 -> 4.55 | BB21: =(BB14*0.25+BB15*0.75+BB16*3+BB17*8+BB18*13+BB19*18+BB20*22.5)/100 -> 9.72 | BC21: =(BC14*0.25+BC15*0.75+BC16*3+BC17*8+BC18*13+BC19*18+BC20*22.5)/100 -> 7.19 | BD21: =(BD14*0.25+BD15*0.75+BD16*3+BD17*8+BD18*13+BD19*18+BD20*22.5)/100 -> 3.825 | BE21: =(BE14*0.25+BE15*0.75+BE16*3+BE17*8+BE18*13+BE19*18+BE20*22.5)/100 -> 2.285 | ... BN21: =(BN14*0.25+BN15*0.75+BN16*3+BN17*8+BN18*13+BN19*18+BN20*22.5)/100 -> 4.655 | CH21: =(CH14*0.25+CH15*0.75+CH16*3+CH17*8+CH18*13+CH19*18+CH20*22.5)/100 -> 8.89 | CI21: =(CI14*0.25+CI15*0.75+CI16*3+CI17*8+CI18*13+CI19*18+CI20*22.5)/100 -> 8.725 | CJ21: =(CJ14*0.25+CJ15*0.75+CJ16*3+CJ17*8+CJ18*13+CJ19*18+CJ20*22.5)/100 -> 6.9425 | CK21: =(CK14*0.25+CK15*0.75+CK16*3+CK17*8+CK18*13+CK19*18+CK20*22.5)/100 -> 17.195 | CL21: =(CL14*0.25+CL15*0.75+CL16*3+CL17*8+CL18*13+CL19*18+CL20*22.5)/100 -> 11.9975 | CM21: =(CM14*0.25+CM15*0.75+CM16*3+CM17*8+CM18*13+CM19*18+CM20*22.5)/100 -> 13.01 | CN21: =(CN14*0.25+CN15*0.75+CN16*3+CN17*8+CN18*13+CN19*18+CN20*22.5)/100 -> 6.9825 | CO21: =(CO14*0.25+CO15*0.75+CO16*3+CO17*8+CO18*13+CO19*18+CO20*22.5)/100 -> 8.735 | ... CW21: =(CW14*0.25+CW15*0.75+CW16*3+CW17*8+CW18*13+CW19*18+CW20*22.5)/100 -> 13.56 | CY21: =(CY14*0.25+CY15*0.75+CY16*3+CY17*8+CY18*13+CY19*18+CY20*22.5)/100 -> 3.045 | CZ21: =(CZ14*0.25+CZ15*0.75+CZ16*3+CZ17*8+CZ18*13+CZ19*18+CZ20*22.5)/100 -> 3.2 | DA21: =(DA14*0.25+DA15*0.75+DA16*3+DA17*8+DA18*11+DA19*18+DA20*22.5)/100 -> 5.14 | DB21: =(DB14*0.25+DB15*0.75+DB16*3+DB17*8+DB18*11+DB19*18+DB20*22.5)/100 -> 10.55 | DC21: =(DC14*0.25+DC15*0.75+DC16*3+DC17*8+DC18*13+DC19*18+DC20*22.5)/100 -> 3.0425 | DD21: =(DD14*0.25+DD15*0.75+DD16*3+DD17*8+DD18*13+DD19*18+DD20*22.5)/100 -> 5.25 | DE21: =(DE14*0.25+DE15*0.75+DE16*3+DE17*8+DE18*13+DE19*18+DE20*22.5)/100 -> 9.4125 | DF21: =(DF14*0.25+DF15*0.75+DF16*3+DF17*8+DF18*13+DF19*18+DF20*22.5)/100 -> 5.4425 | DG21: =(DG14*0.25+DG15*0.75+DG16*3+DG17*8+DG18*13+DG19*18+DG20*22.5)/100 -> 8.76 | DH21: =(DH14*0.25+DH15*0.75+DH16*3+DH17*8+DH18*13+DH19*18+DH20*22.5)/100 -> 8.76 | DI21: =(DI14*0.25+DI15*0.75+DI16*3+DI17*8+DI18*13+DI19*18+DI20*22.5)/100 -> 13.0975 | DJ21: =(DJ14*0.25+DJ15*0.75+DJ16*3+DJ17*8+DJ18*13+DJ19*18+DJ20*22.5)/100 -> 0.4925 | ... FA21: =(FA14*0.25+FA15*0.75+FA16*3+FA17*8+FA18*13+FA19*18+FA20*22.5)/100 -> 7.9475 | FC21: =(FC14*0.25+FC15*0.75+FC16*3+FC17*8+FC18*13+FC19*18+FC20*22.5)/100 -> 3.74 | FE21: =(FE14*0.25+FE15*0.75+FE16*3+FE17*8+FE18*13+FE19*18+FE20*22.5)/100 -> 20.9225 | FF21: =(FF14*0.25+FF15*0.75+FF16*3+FF17*8+FF18*13+FF19*18+FF20*22.5)/100 -> 10.5725 | FG21: =(FG14*0.25+FG15*0.75+FG16*3+FG17*8+FG18*13+FG19*18+FG20*22.5)/100 -> 11.6175 | FH21: =(FH14*0.25+FH15*0.75+FH16*3+FH17*8+FH18*13+FH19*18+FH20*22.5)/100 -> 10.155 | FI21: =(FI14*0.25+FI15*0.75+FI16*3+FI17*8+FI18*13+FI19*18+FI20*22.5)/100 -> 7.2675 | FJ21: =(FJ14*0.25+FJ15*0.75+FJ16*3+FJ17*8+FJ18*13+FJ19*18+FJ20*22.5)/100 -> 4.07 | FK21: =(FK14*0.25+FK15*0.75+FK16*3+FK17*8+FK18*13+FK19*18+FK20*22.5)/100 -> 19.685 | FL21: =(FL14*0.25+FL15*0.75+FL16*3+FL17*8+FL18*13+FL19*18+FL20*22.5)/100 -> 10.1475 | ... FT21: =(FT14*0.25+FT15*0.75+FT16*3+FT17*8+FT18*13+FT19*18+FT20*22.5)/100 -> 4.2275 | FV21: =(FV14*0.25+FV15*0.75+FV16*3+FV17*8+FV18*13+FV19*18+FV20*22.5)/100 -> 3.015 | FW21: =(FW14*0.25+FW15*0.75+FW16*3+FW17*8+FW18*13+FW19*18+FW20*22.5)/100 -> 11.01 | FX21: =(FX14*0.25+FX15*0.75+FX16*3+FX17*8+FX18*13+FX19*18+FX20*22.5)/100 -> 8.8825 | FY21: =(FY14*0.25+FY15*0.75+FY16*3+FY17*8+FY18*13+FY19*18+FY20*22.5)/100 -> 11.61 | FZ21: =(FZ14*0.25+FZ15*0.75+FZ16*3+FZ17*8+FZ18*13+FZ19*18+FZ20*22.5)/100 -> 9.065 | GA21: =(GA14*0.25+GA15*0.75+GA16*3+GA17*8+GA18*13+GA19*18+GA20*22.5)/100 -> 5.6 | GB21: =(GB14*0.25+GB15*0.75+GB16*3+GB17*8+GB18*13+GB19*18+GB20*22.5)/100 -> 4.8175 | GC21: =(GC14*0.25+GC15*0.75+GC16*3+GC17*8+GC18*13+GC19*18+GC20*22.5)/100 -> 3.9475 | ... GS21: =(GS14*0.25+GS15*0.75+GS16*3+GS17*8+GS18*13+GS19*18+GS20*22.5)/100 -> 12.5925 | GV21: =(GV14*0.25+GV15*0.75+GV16*3+GV17*8+GV18*13+GV19*18+GV20*22.5)/100 -> 8.7694404
A22: How long have you worked in your current department?
A23: Less than 6 months | AN23: 7 | AO23: 28 | AQ23: 24 | AR23: 6 | AS23: 8 | AT23: 28 | BG23: 62 | BI23: 38 | BL23: 34 | BM23: 1 | CH23: 12 | CI23: 12 | CJ23: 0 | CK23: 0 | CL23: 4 | CM23: 6 | CN23: 26 | CO23: 10 | CP23: 35 | CQ23: 21 | CS23: 0 | CT23: 0 | CU23: 14 | CV23: 10 | CY23: 36 | CZ23: 28 | DA23: 14 | DC23: 13 | DF23: 41 | DG23: 4 | DH23: 3 | DI23: 5 | DJ23: 65 | DK23: 9 | DL23: 8 | DM23: 0 | DN23: 28 | DP23: 1 | DQ23: 4 | DR23: 1 | DS23: 34 | DT23: 5 | DU23: 2 | DV23: 14 | DW23: 6 | DY23: 28 | EC23: 37 | EE23: 12 | EF23: 0 | EJ23: 4 | EK23: 13 | EL23: 14 | EN23: 3 | EQ23: 8 | EU23: 8 | EX23: 11 | FA23: 16 | FF23: 13 | FG23: 6 | FJ23: 15 | FK23: 12 | FL23: 6 | FM23: 9 | FO23: 20 | FP23: 12 | FQ23: 6 | FT23: 23 | GL23: 9 | GM23: 16 | GN23: 15 | GO23: 7 | GP23: 30 | GV23: =AVERAGE(B23:GS23) -> 14.722222
A24: 6 months to 1 year | B24: 0 | AD24: 12 | AN24: 7 | AO24: 17 | AQ24: 18 | AR24: 5 | AS24: 6 | AT24: 10 | AU24: 39 | AV24: 15 | AX24: 39 | BG24: 0 | BI24: 8 | BL24: 18 | BM24: 1 | CH24: 16 | CI24: 16 | CJ24: 40 | CK24: 5 | CL24: 5 | CM24: 6 | CN24: 18 | CO24: 6 | CP24: 10 | CQ24: 0 | CS24: 5 | CT24: 21 | CU24: 4 | CV24: 20 | CY24: 18 | CZ24: 28 | DA24: 13 | DC24: 27 | DF24: 20 | DG24: 10 | DH24: 4 | DI24: 18 | DJ24: 32 | DK24: 19 | DL24: 2 | DM24: 4 | DN24: 6 | DP24: 3 | DQ24: 6 | DR24: 5 | DS24: 47 | DT24: 10 | DU24: 11 | DV24: 22 | DW24: 8 | DY24: 2 | EC24: 10 | EE24: 9 | EF24: 1 | EJ24: 0 | EK24: 15 | EL24: 15 | EN24: 10 | EQ24: 5 | EU24: 9 | EX24: 19 | FA24: 12 | FF24: 14 | FG24: 8 | FJ24: 18 | FK24: 3 | FL24: 11 | FM24: 11 | FO24: 16 | FP24: 16 | FQ24: 9 | FT24: 11 | GL24: 19 | GM24: 20 | GN24: 15 | GO24: 14 | GP24: 24 | GV24: =AVERAGE(B24:GS24) -> 12.935065
A25: 1 to 5 years | B25: 35 | AD25: 48 | AN25: 46 | AO25: 39 | AQ25: 36 | AR25: 27 | AS25: 52 | AT25: 36 | AU25: 56 | AV25: 39 | AX25: 39 | BG25: 31 | BI25: 16 | BL25: 24 | BM25: 42 | CH25: 28 | CI25: 24 | CJ25: 55 | CK25: 35 | CL25: 33 | CM25: 38 | CN25: 18 | CO25: 42 | CP25: 48 | CQ25: 24 | CS25: 19 | CT25: 16 | CU25: 22 | CV25: 33 | CY25: 36 | CZ25: 44 | DA25: 42 | DC25: 60 | DF25: 9 | DG25: 38 | DH25: 56 | DI25: 28 | DJ25: 2 | DK25: 59 | DL25: 47 | DM25: 18 | DN25: 12 | DP25: 45 | DQ25: 25 | DR25: 33 | DS25: 11 | DT25: 45 | DU25: 53 | DV25: 35 | DW25: 45 | DY25: 62 | EC25: 46 | EE25: 35 | EF25: 34 | EJ25: 54 | EK25: 36 | EL25: 47 | EN25: 68 | EQ25: 43 | EU25: 34 | EX25: 63 | FA25: 43 | FF25: 21 | FG25: 32 | FJ25: 56 | FK25: 11 | FL25: 30 | FM25: 27 | FO25: 29 | FP25: 46 | FQ25: 40 | FT25: 44 | GL25: 31 | GM25: 34 | GN25: 38 | GO25: 36 | GP25: 24 | GV25: =AVERAGE(B25:GS25) -> 36.467532
A26: 6 to 10 years | B26: 16 | AD26: 36 | AN26: 39 | AO26: 6 | AQ26: 10 | AR26: 23 | AS26: 21 | AT26: 26 | AU26: 6 | AV26: 18 | AX26: 7 | BG26: 0 | BI26: 19 | BL26: 16 | BM26: 16 | CH26: 20 | CI26: 22 | CJ26: 5 | CK26: 16 | CL26: 18 | CM26: 25 | CN26: 11 | CO26: 17 | CP26: 8 | CQ26: 10 | CS26: 43 | CT26: 26 | CU26: 25 | CV26: 20 | CY26: 10 | CZ26: 0 | DA26: 24 | DC26: 0 | DF26: 10 | DG26: 21 | DH26: 25 | DI26: 11 | DJ26: 0 | DK26: 10 | DL26: 42 | DM26: 20 | DN26: 9 | DP26: 21 | DQ26: 29 | DR26: 22 | DS26: 4 | DT26: 18 | DU26: 9 | DV26: 8 | DW26: 20 | DY26: 7 | EC26: 5 | EE26: 17 | EF26: 13 | EJ26: 9 | EK26: 28 | EL26: 14 | EN26: 13 | EQ26: 23 | EU26: 17 | EX26: 7 | FA26: 16 | FF26: 18 | FG26: 16 | FJ26: 4 | FK26: 12 | FL26: 17 | FM26: 20 | FO26: 18 | FP26: 16 | FQ26: 16 | FT26: 16 | GL26: 19 | GM26: 8 | GN26: 15 | GO26: 13 | GP26: 11 | GV26: =AVERAGE(B26:GS26) -> 15.922078
A27: 11 to 15 years | B27: 12 | AD27: 4 | AN27: 0 | AO27: 6 | AQ27: 6 | AR27: 12 | AS27: 10 | AT27: 0 | AU27: 0 | AV27: 17 | AX27: 15 | BG27: 0 | BI27: 9 | BL27: 4 | BM27: 27 | CH27: 4 | CI27: 8 | CJ27: 0 | CK27: 9 | CL27: 8 | CM27: 16 | CN27: 7 | CO27: 8 | CP27: 0 | CQ27: 21 | CS27: 10 | CT27: 5 | CU27: 18 | CV27: 9 | CY27: 0 | CZ27: 0 | DA27: 7 | DC27: 0 | DF27: 12 | DG27: 18 | DH27: 5 | DI27: 8 | DJ27: 0 | DK27: 3 | DL27: 1 | DM27: 17 | DN27: 10 | DP27: 4 | DQ27: 13 | DR27: 18 | DS27: 3 | DT27: 17 | DU27: 11 | DV27: 12 | DW27: 17 | DY27: 0 | EC27: 0 | EE27: 14 | EF27: 24 | EJ27: 18 | EK27: 8 | EL27: 10 | EN27: 0 | EQ27: 11 | EU27: 12 | EX27: 0 | FA27: 5 | FF27: 10 | FG27: 12 | FJ27: 2 | FK27: 7 | FL27: 7 | FM27: 10 | FO27: 10 | FP27: 8 | FQ27: 7 | FT27: 4 | GL27: 16 | GM27: 8 | GN27: 10 | GO27: 12 | GP27: 7 | GV27: =AVERAGE(B27:GS27) -> 8.4805195
A28: 16 to 20 years | B28: 7 | AD28: 0 | AN28: 0 | AO28: 0 | AQ28: 4 | AR28: 15 | AS28: 4 | AT28: 0 | AU28: 0 | AV28: 7 | AX28: 0 | BG28: 6 | BI28: 3 | BL28: 3 | BM28: 12 | CH28: 8 | CI28: 7 | CJ28: 0 | CK28: 16 | CL28: 15 | CM28: 6 | CN28: 11 | CO28: 6 | CP28: 0 | CQ28: 17 | CS28: 5 | CT28: 10 | CU28: 8 | CV28: 4 | CY28: 0 | CZ28: 0 | DC28: 0 | DF28: 6 | DG28: 9 | DH28: 2 | DI28: 9 | DJ28: 0 | DL28: 0 | DM28: 22 | DN28: 16 | DP28: 6 | DQ28: 4 | DR28: 7 | DS28: 1 | DT28: 5 | DU28: 4 | DV28: 8 | DW28: 3 | DY28: 0 | EC28: 0 | EE28: 6 | EF28: 13 | EJ28: 4 | EK28: 0 | EL28: 0 | EN28: 3 | EQ28: 5 | EU28: 5 | EX28: 0 | FA28: 3 | FF28: 10 | FG28: 5 | FJ28: 2 | FK28: 6 | FL28: 9 | FM28: 8 | FO28: 5 | FP28: 3 | FQ28: 11 | FT28: 2 | GL28: 4 | GM28: 5 | GN28: 4 | GO28: 6 | GP28: 1 | GV28: =AVERAGE(B28:GS28) -> 5.28
A29: Over 20 years | B29: 10 | AD29: 0 | AN29: 0 | AO29: 6 | AQ29: 3 | AR29: 13 | AS29: 0 | AT29: 0 | AU29: 0 | AV29: 4 | AX29: 0 | BG29: 0 | BI29: 7 | BL29: 0 | BM29: 1 | CH29: 12 | CI29: 9 | CJ29: 0 | CK29: 19 | CL29: 17 | CM29: 3 | CN29: 7 | CO29: 10 | CP29: 0 | CQ29: 7 | CS29: 19 | CT29: 21 | CU29: 8 | CV29: 3 | CY29: 0 | CZ29: 0 | DC29: 0 | DF29: 2 | DG29: 0 | DH29: 4 | DI29: 20 | DJ29: 0 | DL29: 0 | DM29: 18 | DN29: 19 | DP29: 20 | DQ29: 19 | DR29: 14 | DS29: 0 | DT29: 1 | DU29: 10 | DV29: 0 | DW29: 1 | DY29: 0 | EC29: 2 | EE29: 8 | EF29: 16 | EJ29: 9 | EK29: 0 | EL29: 1 | EN29: 3 | EQ29: 6 | EU29: 14 | EX29: 0 | FA29: 5 | FF29: 15 | FG29: 20 | FJ29: 3 | FK29: 50 | FL29: 11 | FM29: 14 | FO29: 2 | FP29: 0 | FQ29: 11 | FT29: 0 | GL29: 2 | GM29: 10 | GN29: 2 | GO29: 12 | GP29: 1 | GV29: =AVERAGE(B29:GS29) -> 6.9866667
A30: AVERAGE | B30: =(B24*0.5+B25*3+B26*8+B27*13+B28*18+B29*25)/100 -> 7.65 | AD30: =(AD24*0.5+AD25*3+AD26*8+AD27*13+AD28*18+AD29*25)/100 -> 4.9 | AN30: =(AN24*0.5+AN25*3+AN26*8+AN27*13+AN28*18+AN29*25)/100 -> 4.535 | AO30: =(AO24*0.5+AO25*3+AO26*8+AO27*13+AO28*18+AO29*25)/100 -> 4.015 | AQ30: =(AQ24*0.5+AQ25*3+AQ26*8+AQ27*13+AQ28*18+AQ29*25)/100 -> 4.22 | AR30: =(AR23*0.25+AR24*0.75+AR25*3+AR26*8+AR27*13+AR28*18+AR29*22.5)/100 -> 9.8875 | AS30: =(AS23*0.25+AS24*0.75+AS25*3+AS26*8+AS27*13+AS28*18+AS29*22.5)/100 -> 5.325 | AT30: =(AT23*0.25+AT24*0.75+AT25*3+AT26*8+AT27*13+AT28*18+AT29*22.5)/100 -> 3.305 | AU30: =(AU24*0.5+AU25*3+AU26*8+AU27*13+AU28*18+AU29*25)/100 -> 2.355 | AV30: =(AV24*0.5+AV25*3+AV26*8+AV27*13+AV28*18+AV29*25)/100 -> 7.155 | AX30: =(AX24*0.5+AX25*3+AX26*8+AX27*13+AX28*18+AX29*25)/100 -> 3.875 | BG30: =AVERAGE(AW30:AZ30) -> 3.875 | BI30: =AVERAGE(AW30:AZ30) -> 3.875 | BL30: =AVERAGE(AW30:AZ30) -> 3.875 | BM30: =(BM23*0.25+BM24*0.75+BM25*3+BM26*8+BM27*13+BM28*18+BM29*22.5)/100 -> 8.445 | CH30: =(CH23*0.25+CH24*0.75+CH25*3+CH26*8+CH27*13+CH28*18+CH29*22.5)/100 -> 7.25 | CI30: =(CI23*0.25+CI24*0.75+CI25*3+CI26*8+CI27*13+CI28*18+CI29*22.5)/100 -> 6.955 | CJ30: =(CJ23*0.25+CJ24*0.75+CJ25*3+CJ26*8+CJ27*13+CJ28*18+CJ29*22.5)/100 -> 2.35 | CK30: =(CK23*0.25+CK24*0.75+CK25*3+CK26*8+CK27*13+CK28*18+CK29*22.5)/100 -> 10.6925 | CL30: =(CL23*0.25+CL24*0.75+CL25*3+CL26*8+CL27*13+CL28*18+CL29*22.5)/100 -> 10.0425 | CM30: =(CM23*0.25+CM24*0.75+CM25*3+CM26*8+CM27*13+CM28*18+CM29*22.5)/100 -> 7.035 | CN30: =(CN23*0.25+CN24*0.75+CN25*3+CN26*8+CN27*13+CN28*18+CN29*22.5)/100 -> 6.085 | CO30: =(CO23*0.25+CO24*0.75+CO25*3+CO26*8+CO27*13+CO28*18+CO29*22.5)/100 -> 7.06 | ... CQ30: =(CQ23*0.25+CQ24*0.75+CQ25*3+CQ26*8+CQ27*13+CQ28*18+CQ29*22.5)/100 -> 8.9375 | CS30: =(CS24*0.5+CS25*3+CS26*8+CS27*13+CS28*18+CS29*25)/100 -> 10.985 | CT30: =(CT24*0.5+CT25*3+CT26*8+CT27*13+CT28*18+CT29*25)/100 -> 10.365 | CU30: =(CU23*0.25+CU24*0.75+CU25*3+CU26*8+CU27*13+CU28*18+CU29*22.5)/100 -> 8.305 | CV30: =(CV23*0.25+CV24*0.75+CV25*3+CV26*8+CV27*13+CV28*18+CV29*22.5)/100 -> 5.33 | CY30: =(CY23*0.25+CY24*0.75+CY25*3+CY26*8+CY27*13+CY28*18+CY29*22.5)/100 -> 2.105 | CZ30: =(CZ23*0.25+CZ24*0.75+CZ25*3+CZ26*8+CZ27*13+CZ28*18+CZ29*22.5)/100 -> 1.6 | DA30: =(DA23*0.25+DA24*0.75+DA25*3+DA26*8+DA27*11+DA28*18+DA29*22.5)/100 -> 4.0825 | DC30: =(DC24*0.5+DC25*3+DC26*8+DC27*13+DC28*18+DC29*25)/100 -> 1.935 | DF30: =(DF24*0.5+DF25*3+DF26*8+DF27*13+DF28*18+DF29*25)/100 -> 4.31 | DG30: =(DG24*0.5+DG25*3+DG26*8+DG27*13+DG28*18+DG29*25)/100 -> 6.83 | DH30: =(DH24*0.5+DH25*3+DH26*8+DH27*13+DH28*18+DH29*25)/100 -> 5.71 | DI30: =(DI24*0.5+DI25*3+DI26*8+DI27*13+DI28*18+DI29*25)/100 -> 9.47 | DJ30: =(DJ24*0.5+DJ25*3+DJ26*8+DJ27*13+DJ28*18+DJ29*25)/100 -> 0.22 | DK30: =(DK24*0.5+DK25*3+DK26*8+DK27*13+DK28*18+DK29*25)/100 -> 3.055 | DL30: =(DL24*0.5+DL25*3+DL26*8+DL27*13+DL28*18+DL29*25)/100 -> 4.91 | DM30: =(DM24*0.5+DM25*3+DM26*8+DM27*13+DM28*18+DM29*25)/100 -> 12.83 | DN30: =(DN24*0.5+DN25*3+DN26*8+DN27*13+DN28*18+DN29*25)/100 -> 10.04 | DP30: =(DP24*0.5+DP25*3+DP26*8+DP27*13+DP28*18+DP29*25)/100 -> 9.645 | DQ30: =(DQ24*0.5+DQ25*3+DQ26*8+DQ27*13+DQ28*18+DQ29*25)/100 -> 10.26 | DR30: =(DR24*0.5+DR25*3+DR26*8+DR27*13+DR28*18+DR29*25)/100 -> 9.875 | DS30: =(DS24*0.5+DS25*3+DS26*8+DS27*13+DS28*18+DS29*25)/100 -> 1.455 | DT30: =(DT24*0.5+DT25*3+DT26*8+DT27*13+DT28*18+DT29*25)/100 -> 6.2 | DU30: =(DU23*0.25+DU24*0.75+DU25*3+DU26*8+DU27*13+DU28*18+DU29*22.5)/100 -> 6.7975 | DV30: =(DV23*0.25+DV24*0.75+DV25*3+DV26*8+DV27*13+DV28*18+DV29*22.5)/100 -> 4.89 | DW30: =(DW23*0.25+DW24*0.75+DW25*3+DW26*8+DW27*13+DW28*18+DW29*22.5)/100 -> 6 | DY30: =(DY23*0.25+DY24*0.75+DY25*3+DY26*8+DY27*13+DY28*18+DY29*22.5)/100 -> 2.505 | EC30: =(EC24*0.5+EC25*3+EC26*8+EC27*13+EC28*18+EC29*25)/100 -> 2.33 | EE30: =(EE23*0.25+EE24*0.75+EE25*3+EE26*8+EE27*13+EE28*18+EE29*22.5)/100 -> 7.2075 | EF30: =(EF23*0.25+EF24*0.75+EF25*3+EF26*8+EF27*13+EF28*18+EF29*22.5)/100 -> 11.1275 | EJ30: =(EJ24*0.5+EJ25*3+EJ26*8+EJ27*13+EJ28*18+EJ29*25)/100 -> 7.65 | EK30: =(EK24*0.5+EK25*3+EK26*8+EK27*13+EK28*18+EK29*25)/100 -> 4.435 | EL30: =(EL24*0.5+EL25*3+EL26*8+EL27*13+EL28*18+EL29*25)/100 -> 4.155 | EN30: =(EN23*0.25+EN24*0.75+EN25*3+EN26*8+EN27*13+EN28*18+EN29*22.5)/100 -> 4.3775 | EQ30: =(EQ24*0.5+EQ25*3+EQ26*8+EQ27*13+EQ28*18+EQ29*25)/100 -> 6.985 | EU30: =(EU24*0.5+EU25*3+EU26*8+EU27*13+EU28*18+EU29*25)/100 -> 8.385 | EX30: =(EX24*0.5+EX25*3+EX26*8+EX27*13+EX28*18+EX29*25)/100 -> 2.545 | FA30: =(FA24*0.5+FA25*3+FA26*8+FA27*13+FA28*18+FA29*25)/100 -> 5.07 | FF30: =(FF23*0.25+FF24*0.75+FF25*3+FF26*8+FF27*13+FF28*18+FF29*22.5)/100 -> 8.6825 | FG30: =(FG23*0.25+FG24*0.75+FG25*3+FG26*8+FG27*13+FG28*18+FG29*22.5)/100 -> 9.275 | FJ30: =(FJ24*0.5+FJ25*3+FJ26*8+FJ27*13+FJ28*18+FJ29*25)/100 -> 3.46 | FK30: =(FK24*0.5+FK25*3+FK26*8+FK27*13+FK28*18+FK29*25)/100 -> 15.795 | FL30: =(FL24*0.5+FL25*3+FL26*8+FL27*13+FL28*18+FL29*25)/100 -> 7.595 | FM30: =(FM24*0.5+FM25*3+FM26*8+FM27*13+FM28*18+FM29*25)/100 -> 8.705 | FO30: =(FO24*0.5+FO25*3+FO26*8+FO27*13+FO28*18+FO29*25)/100 -> 5.09 | FP30: =(FP24*0.5+FP25*3+FP26*8+FP27*13+FP28*18+FP29*25)/100 -> 4.32 | FQ30: =(FQ23*0.25+FQ24*0.75+FQ25*3+FQ26*8+FQ27*13+FQ28*18+FQ29*22.5)/100 -> 7.9275 | FT30: =(FT23*0.25+FT24*0.75+FT25*3+FT26*8+FT27*13+FT28*18+FT29*22.5)/100 -> 3.62 | GL30: =(GL24*0.5+GL25*3+GL26*8+GL27*13+GL28*18+GL29*25)/100 -> 5.845 | GM30: =(GM24*0.5+GM25*3+GM26*8+GM27*13+GM28*18+GM29*25)/100 -> 6.2 | GN30: =(GN24*0.5+GN25*3+GN26*8+GN27*13+GN28*18+GN29*25)/100 -> 4.935 | GO30: =(GO24*0.5+GO25*3+GO26*8+GO27*13+GO28*18+GO29*25)/100 -> 7.83 | GP30: =(GP24*0.5+GP25*3+GP26*8+GP27*13+GP28*18+GP29*25)/100 -> 3.06 | GV30: =(GV24*0.5+GV25*3+GV26*8+GV27*13+GV28*18+GV29*25)/100 -> 6.2320017
A31: Do you have a second job?
A32: Yes | B32: 9 | C32: 10 | D32: 1 | E32: 13 | G32: 12 | H32: 13 | J32: 4 | K32: 5 | M32: 15 | N32: 10 | O32: 16 | P32: 15 | Q32: 6 | R32: 11 | S32: 5 | T32: 7 | U32: 9 | V32: 16 | W32: 11 | X32: 0 | Y32: 12 | Z32: 5 | AA32: 19 | AB32: 10 | AC32: 18 | AE32: 0 | AF32: 7 | AG32: 7 | AH32: 8 | AI32: 8 | AJ32: 11 | AK32: 14 | AL32: 17 | AM32: 4 | AN32: 18 | AO32: 33 | AP32: 5 | AQ32: 39 | AR32: 17 | AS32: 6 | AT32: 7 | AZ32: 10 | BB32: 18 | BC32: 3 | BD32: 23 | BF32: 12 | BG32: 19 | BH32: 7 | BJ32: 12 | BK32: 14 | BL32: 14 | BM32: 18 | BN32: 19 | BO32: 8 | BP32: 13 | BQ32: 9 | BR32: 9 | BS32: 13 | BT32: 5 | BU32: 13 | BV32: 4 | BW32: 15 | BX32: 4 | BY32: 16 | BZ32: 16 | CA32: 9 | CB32: 12 | CC32: 14 | CD32: 22 | CE32: 10 | CF32: 12 | CG32: 8 | CH32: 12 | CI32: 13 | CJ32: 7 | CK32: 9 | CM32: 6 | CN32: 7 | CO32: 4 | CQ32: 3 | CR32: 8 | CS32: 0 | CT32: 11 | CV32: 9 | CW32: 12 | CX32: 4 | DA32: 9 | DD32: 22 | DE32: 0 | DH32: 12 | DI32: 11 | DJ32: 11 | DK32: 8 | DL32: 17 | DM32: 2 | DN32: 15 | DO32: 8 | DP32: 16 | DQ32: 8 | DR32: 11 | DS32: 9 | DT32: 9 | DU32: 9 | DV32: 19 | DW32: 21 | DX32: 7 | DY32: 2 | DZ32: 1 | EA32: 4 | EB32: 3 | EC32: 7 | ED32: 8 | EE32: 23 | EG32: 6 | EH32: 0 | EI32: 6 | EJ32: 4 | EK32: 8 | EL32: 16 | EM32: 10 | EN32: 3 | EO32: 4 | EP32: 6 | EQ32: 8 | ER32: 18 | ES32: 4 | ET32: 10 | EU32: 4 | EV32: 12 | EW32: 12 | EX32: 17 | EY32: 7 | EZ32: 9 | FA32: 9 | FB32: 11 | FC32: 13 | FE32: 8 | FN32: 9 | FO32: 7 | FP32: 9 | FQ32: 5 | FR32: 5 | FS32: 6 | FU32: 10 | FV32: 8 | FW32: 3 | FX32: 4 | FY32: 18 | FZ32: 7 | GA32: 18 | GB32: 11 | GC32: 7 | GD32: 6 | GE32: 14 | GF32: 7 | GG32: 9 | GJ32: 8 | GL32: 7 | GM32: 13 | GN32: 10 | GO32: 11 | GP32: 9 | GQ32: 7 | GR32: 3 | GS32: 12 | GV32: =AVERAGE(B32:GS32) -> 10.054545
A33: No | B33: 91 | C33: 90 | D33: 99 | E33: 87 | G33: 88 | H33: 87 | J33: 96 | K33: 95 | M33: 85 | N33: 90 | O33: 84 | P33: 85 | Q33: 94 | R33: 89 | S33: 95 | T33: 93 | U33: 91 | V33: 84 | W33: 89 | X33: 100 | Y33: 88 | Z33: 95 | AA33: 81 | AB33: 84 | AC33: 82 | AE33: 100 | AF33: 93 | AG33: 93 | AH33: 92 | AI33: 92 | AJ33: 89 | AK33: 86 | AL33: 83 | AM33: 96 | AN33: 82 | AO33: 67 | AP33: 95 | AQ33: 61 | AR33: 83 | AS33: 94 | AT33: 93 | AZ33: 90 | BB33: 82 | BC33: 97 | BD33: 77 | BF33: 88 | BG33: 81 | BH33: 93 | BJ33: 88 | BK33: 86 | BL33: 86 | BM33: 82 | BN33: 81 | BO33: 92 | BP33: 87 | BQ33: 91 | BR33: 91 | BS33: 87 | BT33: 95 | BU33: 87 | BV33: 96 | BW33: 85 | BX33: 96 | BY33: 84 | BZ33: 84 | CA33: 91 | CB33: 88 | CC33: 86 | CD33: 78 | CE33: 90 | CF33: 88 | CG33: 92 | CH33: 88 | CI33: 87 | CJ33: 93 | CK33: 91 | CM33: 94 | CN33: 93 | CO33: 96 | CQ33: 97 | CR33: 92 | CS33: 100 | CT33: 89 | CV33: 91 | CW33: 88 | CX33: 96 | DA33: 91 | DD33: 78 | DE33: 100 | DH33: 88 | DI33: 89 | DJ33: 89 | DK33: 92 | DL33: 83 | DM33: 98 | DN33: 85 | DO33: 92 | DP33: 84 | DQ33: 92 | DR33: 89 | DS33: 91 | DT33: 91 | DU33: 91 | DV33: 81 | DW33: 79 | DX33: 93 | DY33: 98 | DZ33: 99 | EA33: 96 | EB33: 97 | EC33: 93 | ED33: 92 | EE33: 77 | EG33: 94 | EH33: 100 | EI33: 94 | EJ33: 96 | EK33: 92 | EL33: 84 | EM33: 90 | EN33: 97 | EO33: 96 | EP33: 94 | EQ33: 92 | ER33: 82 | ES33: 96 | ET33: 90 | EU33: 96 | EV33: 88 | EW33: 88 | EX33: 83 | EY33: 93 | EZ33: 91 | FA33: 91 | FB33: 89 | FC33: 86 | FE33: 92 | FN33: 91 | FO33: 93 | FP33: 91 | FQ33: 95 | FR33: 95 | FS33: 94 | FU33: 90 | FV33: 92 | FW33: 97 | FX33: 96 | FY33: 82 | FZ33: 93 | GA33: 82 | GB33: 89 | GC33: 93 | GD33: 94 | GE33: 86 | GF33: 93 | GG33: 91 | GJ33: 92 | GL33: 93 | GM33: 87 | GN33: 90 | GO33: 89 | GP33: 91 | GQ33: 93 | GR33: 97 | GS33: 88 | GV33: =AVERAGE(B33:GS33) -> 89.90303
A34: If you have a second job, do you typically work at that job:
A35: Before your shift at XXX starts | AQ35: 11 | BD35: 5 | BH35: 1 | BJ35: 0 | BK35: 3 | BL35: 3 | BM35: 0 | BN35: 0 | BP35: 4 | BS35: 3 | BW35: 4 | BZ35: 4 | CA35: 0 | CC35: 1 | CL35: 3 | CO35: 0 | CQ35: 4 | CV35: 6 | CW35: 0 | DA35: 0 | DD35: 8 | DE35: 0 | DH35: 1 | DL35: 6 | DO35: 2 | DR35: 0 | DS35: 5 | DT35: 1 | DV35: 5 | DW35: 10 | DX35: 2 | DY35: 0 | DZ35: 0 | EC35: 0 | EE35: 12 | EJ35: 0 | EK35: 4 | EL35: 5 | EU35: 2 | EX35: 7 | FA35: 0 | FC35: 4 | FE35: 3 | FO35: 1 | FP35: 2 | FQ35: 1 | GQ35: 4 | GV35: =AVERAGE(B35:GS35) -> 2.9148936
A36: After you have worked your shift at XXX | AQ36: 11 | BD36: 16 | BH36: 1 | BJ36: 0 | BK36: 3 | BL36: 10 | BM36: 0 | BN36: 0 | BP36: 8 | BS36: 6 | BW36: 3 | BZ36: 12 | CA36: 0 | CC36: 6 | CL36: 6 | CO36: 2 | CQ36: 0 | CV36: 3 | CW36: 7 | DA36: 2 | DD36: 10 | DE36: 0 | DH36: 6 | DL36: 12 | DO36: 2 | DR36: 8 | DS36: 5 | DT36: 6 | DV36: 12 | DW36: 12 | DX36: 0 | DY36: 2 | DZ36: 1 | EC36: 3 | EE36: 13 | EJ36: 0 | EK36: 5 | EL36: 9 | EU36: 1 | EX36: 11 | FA36: 5 | FC36: 7 | FE36: 3 | FO36: 5 | FP36: 9 | FQ36: 2 | GQ36: 5 | GV36: =AVERAGE(B36:GS36) -> 5.3191489
A37: Only on days that you don't work at XXX | AQ37: 20 | BD37: 13 | BH37: 6 | BJ37: 15 | BK37: 11 | BL37: 5 | BM37: 19 | BN37: 23 | BP37: 4 | BS37: 11 | BW37: 7 | BZ37: 4 | CA37: 10 | CC37: 10 | CL37: 4 | CO37: 2 | CQ37: 0 | CV37: 0 | CW37: 7 | DA37: 10 | DD37: 8 | DE37: 0 | DH37: 6 | DL37: 4 | DO37: 4 | DR37: 3 | DS37: 1 | DT37: 1 | DV37: 8 | DW37: 3 | DX37: 2 | DY37: 1 | DZ37: 0 | EC37: 6 | EE37: 6 | EJ37: 5 | EK37: 1 | EL37: 6 | EU37: 1 | EX37: 6 | FA37: 6 | FC37: 2 | FE37: 3 | FO37: 1 | FP37: 2 | FQ37: 3 | GQ37: 0 | GV37: =AVERAGE(B37:GS37) -> 5.7446809
A38: I don't work at a second job | AQ38: 57 | BD38: 65 | BH38: 91 | BJ38: 85 | BK38: 82 | BL38: 82 | BM38: 81 | BN38: 77 | BP38: 84 | BS38: 80 | BW38: 86 | BZ38: 79 | CA38: 90 | CC38: 83 | CL38: 87 | CO38: 96 | CQ38: 96 | CV38: 92 | CW38: 86 | DA38: 88 | DD38: 74 | DE38: 100 | DH38: 87 | DL38: 78 | DO38: 92 | DR38: 88 | DS38: 89 | DT38: 91 | DV38: 74 | DW38: 75 | DX38: 96 | DY38: 96 | DZ38: 99 | EC38: 91 | EE38: 68 | EJ38: 95 | EK38: 90 | EL38: 81 | EU38: 96 | EX38: 76 | FA38: 89 | FC38: 76 | FE38: 91 | FO38: 93 | FP38: 88 | FQ38: 94 | GQ38: 91
A39: Are you a student?
A40: Yes | H40: 10 | J40: 6 | K40: 5 | M40: 8 | N40: 16 | O40: 7 | P40: 4 | Q40: 18 | S40: 3 | T40: 12 | U40: 5 | V40: 26 | W40: 30 | X40: 0 | Y40: 3 | Z40: 7 | AA40: 6 | AB40: 5 | AC40: 15 | AE40: 11 | AF40: 0 | AG40: 8 | AH40: 3 | AI40: 14 | AJ40: 9 | AK40: 17 | AL40: 10 | AM40: 0 | AN40: 7 | AO40: 6 | AP40: 15 | AQ40: 4 | AR40: 4 | AS40: 17 | AT40: 7 | AU40: 17 | AV40: 20 | AX40: 10 | AY40: 32 | AZ40: 2 | BA40: 13 | BB40: 3 | BC40: 14 | BD40: 13 | BF40: 22 | BG40: 29 | BH40: 11 | BI40: 9 | BJ40: 4 | BK40: 1 | BL40: 8 | BM40: 7 | BN40: 12 | BO40: 31 | BP40: 11 | BQ40: 5 | BR40: 4 | BS40: 5 | BT40: 14 | BU40: 5 | BV40: 4 | BW40: 0 | BX40: 8 | BY40: 4 | BZ40: 3 | CB40: 10 | CC40: 22 | CD40: 0 | CE40: 13 | CF40: 12 | CG40: 6 | CH40: 4 | CI40: 11 | CJ40: 12 | CK40: 5 | CL40: 5 | CM40: 3 | CN40: 11 | CO40: 3 | CP40: 9 | CQ40: 17 | CR40: 4 | CS40: 10 | CT40: 16 | CU40: 3 | CV40: 6 | CW40: 0 | CX40: 1 | CY40: 14 | CZ40: 8 | DA40: 6 | DC40: 7 | DD40: 5 | DE40: 4 | DH40: 21 | DI40: 4 | DJ40: 10 | DK40: 8 | DL40: 3 | DM40: 0 | DN40: 2 | DO40: 2 | DP40: 1 | DQ40: 1 | DR40: 8 | DS40: 14 | DT40: 14 | DU40: 2 | DV40: 8 | DW40: 15 | DX40: 4 | DY40: 37 | DZ40: 3 | EA40: 7 | EB40: 2 | EC40: 10 | ED40: 14 | EE40: 11 | EF40: 10 | EG40: 13 | EH40: 6 | EI40: 6 | EJ40: 0 | EK40: 7 | EL40: 10 | EM40: 7 | EN40: 3 | EO40: 2 | EP40: 6 | EQ40: 0 | ER40: 18 | ES40: 10 | ET40: 12 | EU40: 8 | EV40: 4 | EW40: 14 | EX40: 21 | EY40: 8 | EZ40: 5 | FA40: 6 | FB40: 14 | FC40: 2 | FD40: 6 | FE40: 3 | FF40: 9 | FG40: 5 | FJ40: 8 | FK40: 1 | FL40: 1 | FM40: 3 | FN40: 8 | FO40: 8 | FP40: 6 | FQ40: 16 | FR40: 2 | FS40: 4 | FT40: 22 | FU40: 2 | FV40: 7 | FW40: 1 | FX40: 3 | FY40: 1 | FZ40: 2 | GA40: 6 | GB40: 6 | GC40: 14 | GD40: 2 | GE40: 2 | GF40: 2 | GG40: 3 | GJ40: 7 | GL40: 5 | GM40: 2 | GN40: 4 | GO40: 4 | GP40: 7 | GQ40: 4 | GR40: 9 | GS40: 1 | GV40: =AVERAGE(B40:GS40) -> 8.1284916
...

Sheet Deviations
A1: Change log
A3: Date | B3: Data link / cell | C3: Column / company | D3: Company | E3: Change | F3: Who | G3: Undone
A4: 44929 | B4: =data!GE21 -> 12.2825 | C4: GD and forward incl Total | D4: Essity South Glenn | E4: Changed the weight of 'Over 20' in the Average from 22.5 to 25 | F4: Erika & Jim | G4: Y
A5: 44929 | B5: =data!GE57 -> 46.22 | C5: GD and forward incl Total | D5: Essity South Glenn | E5: Changed the weight of '25 and under' from 22.5 to 23, 'over 50' from 57.5 to 60 | F5: Erika & Jim | G5: Y
A6: 44929 | B6: =data!GE238 -> 6.4081633 | C6: GD and forward incl Total | D6: Essity South Glenn | E6: Changed weight of 'less than 5 hours' from 4.5 to 4, and 'over 9 hours' from 9.5 to 10 | F6: Erika & Jim | G6: Y
A7: 44929 | B7: =data!GE256 -> 6.035753 | C7: GD and forward incl Total | D7: Essity South Glenn | E7: Changed weight of 'less than 5 hours' from 4.5 to 4, and 'over 9 hours' from 9.5 to 10 | F7: Erika & Jim | G7: Y
A8: 44929 | B8: =data!GE264 -> 7.45 | C8: GD and forward incl Total | D8: Essity South Glenn | E8: Changed weight of 'less than 5 hours' from 4.5 to 4, and 'over 9 hours' from 9.5 to 10 | F8: Erika & Jim | G8: Y
A9: 44929 | B9: =data!GE272 -> 6.8030303 | C9: GD and forward incl Total | D9: Essity South Glenn | E9: Changed weight of 'less than 5 hours' from 4.5 to 4, and 'over 9 hours' from 9.5 to 10 | F9: Erika & Jim | G9: Y
A10: 44929 | B10: =data!GE314 -> 11.5 | C10: GD and forward incl Total | D10: Essity South Glenn | E10: Chanded weight of 'more than 30 min' from 40 to 35 | F10: Erika & Jim | G10: Y
A13: Co | B13: Questions not found in norms
A14: BD Sparks | B14: Q47. How long is your scheduled lunch break?
A15: BD Sparks | B15: Q48. What is your preferred length for your lunch break?
A16: BD Sparks | B16: Q56. Would you be willing to work a scheduled overtime shift on one Saturday each month if it was part of your normal schedule?
A17: BD Columbus | B17: Q 14. Do you use an alarm clock to wake you on days that you work?
A18: BD Columbus | B18: 15. How many hours of sleep do you get on the days you are scheduled to work?
A19: BD Columbus | B19: Q 18. On days that I work, the quality of my sleep is good.
A20: BD Columbus | B20: 56. If you could have 3 days off in a week, which do you prefer?
A21: BD Covington | B21: 53. Would you be willing to work a scheduled overtime shift on one Saturday of each month if it was part of your normal schedule?
A22: Hemlock Legacy | B22: 11. Do you normally use an alarm clock to wake on your days off?
A23: Hemlock Legacy | B23: 42 If you could have 3 days off in a week, which do you prefer?
A24: UTZ P3 | B24: 14 How many hours of sleep do you get when you are working?
... A26: UTZ P3 | B26: 44 Which do you prefer?

Sheet Additions
A1: Added
A2: 44972 | B2: Essity Neenah | H2: Monelez How long
A3: 44960 | B3: Essity South Glen Falls | I3: weight | J3: % | K3: Average
A4: 44972 | B4: Essity Middletown | H4: l10 | I4: 5 | J4: 54 | K4: =I4*J4 -> 270
A5: 44982 | B5: Essity Harrodsburg | H5: 45585 | I5: 15 | J5: 27 | K5: =I5*J5 -> 405
A6: 44982 | B6: BD Four Oaks NC | H6: 21-30 | I6: 25 | J6: 13 | K6: =I6*J6 -> 325
A7: 44985 | B7: BD Sparks MD | H7: m30 | I7: 35 | J7: 7 | K7: =I7*J7 -> 245
A8: 44984 | B8: Andersen Windows Maintenance | K8: =SUM(K4:K7) -> 1245
A9: 44985 | B9: BD Columbus NE | K9: =K8/100 -> 12.45
A10: 2/29/2023 | B10: BD Covington GA
A11: 44990 | B11: Hemlock Legacy
A12: 44991 | B12: UTZ Plant 3
A13: 44992 | B13: UTZ Plant 4
A14: 44993 | B14: UTZ Plant 2
A15: 45014 | B15: Hemlock Finishing
B16: Campbells Beloit WE
A17: 45404 | B17: Mondelez

Sheet Averages before additions
B1: Industry
B2: Headcount
B3: Standard Questions | C3: Averages
A4: 1 | B4: What Department do you work in?
A6: 2 | B6: What is your job title?
A8: 3 | B8: What crew are you assigned to?
A9: 4 | B9: How long have you worked at this facility?
B10: Less than 1 year | C10: 8.8333333
B11: 1 to 5 years | C11: 20
B12: 6 to 10 years | C12: 11.666667
B13: 11 to 15 years | C13: 13.5
B14: 16 to 20 years | C14: 17.333333
B15: Over 20 years | C15: 27.166667
B16: AVERAGE | C16: 12.2525
A17: 5 | B17: Do you have a second job?
B18: Yes | C18: 9.1111111
B19: No | C19: 90.888889
A20: 6 | B20: Do you have children at home that require childcare when you are at work?
B21: Yes | C21: 28.375
B22: No | C22: 71.625
A23: 7 | B23: What is your gender?
B24: Female | C24: 33
B25: Male | C25: 67
A26: 8 | B26: What is your age group?
B27: Under 25 | C27: 4.5
B28: 26 to 30 | C28: 7.5
B29: 31 to 35 | C29: 10.666667
B30: 36 to 40 | C30: 16.333333
B31: 41 to 45 | C31: 25.666667
B32: 46 to 50 | C32: 15.5
B33: 50 to 55 | C33: 9.8333333
B34: Over 55 | C34: 8.1666667
B35: AVERAGE | C35: 40.795833
A36: 9 | B36: Which best describes your spouse or domestic partner's work status?
B37: Does not work outside of the home | C37: 18.444444
B38: Works a different schedule for this company | C38: 4.6666667
B39: Work a different schedule elsewhere | C39: 42.444444
B40: Works the same schedule at this company | C40: 4.6666667
B41: Works the same schedule elsewhere | C41: 11.333333
B42: I live alone | C42: 18.666667
...
